<?xml version="1.0" encoding="utf-8"?>
<!-- This URDF was automatically created by SolidWorks to URDF Exporter! Originally created by Stephen Brawner (brawner@gmail.com) 
     Commit Version: 1.6.0-1-g15f4949  Build Version: 1.6.7594.29634
     For more information, please see http://wiki.ros.org/sw_urdf_exporter -->
<robot
  name="Brazo">
  <link
    name="base_link">
    <inertial>
      <origin
        xyz="-0.00181988431412317 -0.000560482873102286 -0.61470415911321"
        rpy="0 0 0" />
      <mass
        value="75.0489897701372" />
      <inertia
        ixx="6.14731848369995"
        ixy="-6.69432903033991E-07"
        ixz="-3.7345784718265E-10"
        iyy="7.21348803311348"
        iyz="-1.31093747276007E-11"
        izz="10.2682273430131" />
    </inertial>
    <visual>
      <origin
        xyz="0 0 0"
        rpy="0 0 0" />
      <geometry>
        <mesh
          filename="package://Brazo/meshes/base_link.STL" />
      </geometry>
      <material
        name="">
        <color
          rgba="0.898039215686275 0.917647058823529 0.929411764705882 1" />
      </material>
    </visual>
    <collision>
      <origin
        xyz="0 0 0"
        rpy="0 0 0" />
      <geometry>
        <mesh
          filename="package://Brazo/meshes/base_link.STL" />
      </geometry>
    </collision>
  </link>
  <link
    name="link1">
    <inertial>
      <origin
        xyz="-3.79239522008135E-08 0.0595163289716696 -1.31416802995332E-08"
        rpy="0 0 0" />
      <mass
        value="0.263324869173552" />
      <inertia
        ixx="0.000419151866392649"
        ixy="1.7150083972612E-10"
        ixz="-2.00516992113018E-05"
        iyy="0.000336953356034609"
        iyz="5.55614629953305E-11"
        izz="0.000430385608016396" />
    </inertial>
    <visual>
      <origin
        xyz="0 0 0"
        rpy="0 0 0" />
      <geometry>
        <mesh
          filename="package://Brazo/meshes/link1.STL" />
      </geometry>
      <material
        name="">
        <color
          rgba="0.8 0 0 1" />
      </material>
    </visual>
    <collision>
      <origin
        xyz="0 0 0"
        rpy="0 0 0" />
      <geometry>
        <mesh
          filename="package://Brazo/meshes/link1.STL" />
      </geometry>
    </collision>
  </link>
  <joint
    name="art1"
    type="continuous">
    <origin
      xyz="0 0 -0.0900000000000001"
      rpy="-1.5707963267949 0 0" />
    <parent
      link="base_link" />
    <child
      link="link1" />
    <axis
      xyz="0 1 0" />
  </joint>
  <link
    name="link2">
    <inertial>
      <origin
        xyz="-1.19348975147204E-15 0 -0.20314071299586"
        rpy="0 0 0" />
      <mass
        value="0.834989795001253" />
      <inertia
        ixx="0.016278958538123"
        ixy="-3.29996421914181E-18"
        ixz="-8.8626751337112E-17"
        iyy="0.0160955017764778"
        iyz="-1.05305164357569E-17"
        izz="0.00134239749278552" />
    </inertial>
    <visual>
      <origin
        xyz="0 0 0"
        rpy="0 0 0" />
      <geometry>
        <mesh
          filename="package://Brazo/meshes/link2.STL" />
      </geometry>
      <material
        name="">
        <color
          rgba="0.8 0 0 1" />
      </material>
    </visual>
    <collision>
      <origin
        xyz="0 0 0"
        rpy="0 0 0" />
      <geometry>
        <mesh
          filename="package://Brazo/meshes/link2.STL" />
      </geometry>
    </collision>
  </link>
  <joint
    name="art2"
    type="continuous">
    <origin
      xyz="0 0.0899999999999999 0"
      rpy="-1.63627817954981 -0.920330158191558 -3.05937644887765" />
    <parent
      link="link1" />
    <child
      link="link2" />
    <axis
      xyz="0 1 0" />
  </joint>
  <link
    name="link3">
    <inertial>
      <origin
        xyz="0.16680656513501 -5.70128300125816E-09 0.00717597481108504"
        rpy="0 0 0" />
      <mass
        value="0.2763124263045" />
      <inertia
        ixx="8.56579184194442E-05"
        ixy="3.13764967538311E-09"
        ixz="-0.00025023080341864"
        iyy="0.00590023057093252"
        iyz="3.45016484132323E-10"
        izz="0.00589148672269636" />
    </inertial>
    <visual>
      <origin
        xyz="0 0 0"
        rpy="0 0 0" />
      <geometry>
        <mesh
          filename="package://Brazo/meshes/link3.STL" />
      </geometry>
      <material
        name="">
        <color
          rgba="0.8 0 0 1" />
      </material>
    </visual>
    <collision>
      <origin
        xyz="0 0 0"
        rpy="0 0 0" />
      <geometry>
        <mesh
          filename="package://Brazo/meshes/link3.STL" />
      </geometry>
    </collision>
  </link>
  <joint
    name="art3"
    type="continuous">
    <origin
      xyz="0 0 -0.4"
      rpy="3.14159265358979 1.52104524026106 -3.14159265358979" />
    <parent
      link="link2" />
    <child
      link="link3" />
    <axis
      xyz="0 1 0" />
  </joint>
  <link
    name="link4">
    <inertial>
      <origin
        xyz="-0.00670046236247063 -2.52427212465989E-09 0.0364615596097297"
        rpy="0 0 0" />
      <mass
        value="0.0467692235501628" />
      <inertia
        ixx="5.23318706520618E-05"
        ixy="-4.83405643564706E-12"
        ixz="9.344089536118E-06"
        iyy="5.40620456483131E-05"
        iyz="-1.12962729583799E-12"
        izz="3.20180738848132E-06" />
    </inertial>
    <visual>
      <origin
        xyz="0 0 0"
        rpy="0 0 0" />
      <geometry>
        <mesh
          filename="package://Brazo/meshes/link4.STL" />
      </geometry>
      <material
        name="">
        <color
          rgba="0.898039215686275 0.917647058823529 0.929411764705882 1" />
      </material>
    </visual>
    <collision>
      <origin
        xyz="0 0 0"
        rpy="0 0 0" />
      <geometry>
        <mesh
          filename="package://Brazo/meshes/link4.STL" />
      </geometry>
    </collision>
  </link>
  <joint
    name="art4"
    type="continuous">
    <origin
      xyz="0.399630364374733 0 0.0171922037481637"
      rpy="1.32827105796681 1.57079631189374 1.32827105796681" />
    <parent
      link="link3" />
    <child
      link="link4" />
    <axis
      xyz="0 1 0" />
  </joint>
  <link
    name="tool">
    <inertial>
      <origin
        xyz="-1.55431223447522E-15 -0.00999999999999757 -0.0014967868831933"
        rpy="0 0 0" />
      <mass
        value="4.21250252725669E-05" />
      <inertia
        ixx="1.35483910449139E-10"
        ixy="-1.0097419586829E-27"
        ixz="9.37040537657727E-26"
        iyy="1.35483910449139E-10"
        iyz="-8.88572923640948E-26"
        izz="2.6394698335285E-10" />
    </inertial>
    <visual>
      <origin
        xyz="0 0 0"
        rpy="0 0 0" />
      <geometry>
        <mesh
          filename="package://Brazo/meshes/tool.STL" />
      </geometry>
      <material
        name="">
        <color
          rgba="1 1 1 0.32" />
      </material>
    </visual>
    <collision>
      <origin
        xyz="0 0 0"
        rpy="0 0 0" />
      <geometry>
        <mesh
          filename="package://Brazo/meshes/tool.STL" />
      </geometry>
    </collision>
  </link>
  <joint
    name="art5"
    type="fixed">
    <origin
      xyz="-0.0097887 0.0059229 0.097845"
      rpy="2.9946 0.10726 2.1968" />
    <parent
      link="link4" />
    <child
      link="tool" />
    <axis
      xyz="0 0 0" />
  </joint>
</robot>